<mujocoinclude>
  <body name="base" pos="0 0 0">
    <!-- robot view -->
    <camera mode="fixed" name="robotview" pos="1.2 0 1" quat="0.653 0.271 0.271 0.653"/>
    <inertial diaginertia="0 0 0" mass="0" pos="0 0 0"/>
    <!-- mount attached here -->
    <body name="link0" pos="0 0 0">
      <site name="right_center" pos="0 0 0" size="0.01" rgba="1 0.3 0.3 -1" group="2"/>
      <inertial pos="0 0 0.05" mass="4" diaginertia="0.4 0.4 0.4"/>
        <geom name="robot0_g0_vis" type="mesh" contype="0" conaffinity="0" group="1" material="robot0_Shell010_001" mesh="robot0_link0_vis_0"/>
        <geom name="robot0_g1_vis" type="mesh" contype="0" conaffinity="0" group="1" material="robot0_Shell009_001" mesh="robot0_link0_vis_1"/>
        <geom name="robot0_g2_vis" type="mesh" contype="0" conaffinity="0" group="1" material="robot0_Shell003_001" mesh="robot0_link0_vis_2"/>
        <geom name="robot0_g3_vis" type="mesh" contype="0" conaffinity="0" group="1" material="robot0_Shell_001" mesh="robot0_link0_vis_3"/>
        <geom name="robot0_g4_vis" type="mesh" contype="0" conaffinity="0" group="1" material="robot0_Shell002_001" mesh="robot0_link0_vis_4"/>
        <geom name="robot0_g5_vis" type="mesh" contype="0" conaffinity="0" group="1" material="robot0_Shell001_001" mesh="robot0_link0_vis_5"/>
        <geom name="robot0_g6_vis" type="mesh" contype="0" conaffinity="0" group="1" material="robot0_Face636_001" mesh="robot0_link0_vis_6"/>
        <geom name="robot0_g7_vis" type="mesh" contype="0" conaffinity="0" group="1" material="robot0_Part__Feature018_001" mesh="robot0_link0_vis_7"/>
        <geom name="robot0_g8_vis" type="mesh" contype="0" conaffinity="0" group="1" material="robot0_Part__Feature019_001" mesh="robot0_link0_vis_8"/>
        <geom name="robot0_g9_vis" type="mesh" contype="0" conaffinity="0" group="1" material="robot0_Part__Feature023_001" mesh="robot0_link0_vis_9"/>
        <geom name="robot0_g10_vis" type="mesh" contype="0" conaffinity="0" group="1" material="robot0_Part__Feature022_001" mesh="robot0_link0_vis_10"/>
        <geom name="robot0_g11_vis" type="mesh" contype="0" conaffinity="0" group="1" material="robot0_Part__Feature017_001" mesh="robot0_link0_vis_11"/>
        <geom name="robot0_link0_collision" type="mesh" rgba="0 0.5 0 1" mesh="robot0_link0" group="3"/>
        <site name="robot0_right_center" pos="0 0 0" size="0.01" group="2" rgba="1 0.3 0.3 1"/>
      <body name="robot0_link1" pos="0 0 0.333">
          <inertial pos="0 0 -0.07" mass="3" diaginertia="0.3 0.3 0.3"/>
          <joint name="robot0_joint1" pos="0 0 0" axis="0 0 1" limited="true" range="-2.8973 2.8973" armature="5" damping="0.1" frictionloss="0.1"/>
          <geom name="robot0_g12_vis" type="mesh" contype="0" conaffinity="0" group="1" material="robot0_Part__Feature_001" mesh="robot0_link1_vis"/>
          <geom name="robot0_link1_collision" type="mesh" rgba="0 0.5 0 1" mesh="robot0_link1" group="3"/>
          <body name="robot0_link2" quat="0.707107 -0.707107 0 0">
            <inertial pos="0 -0.1 0" mass="3" diaginertia="0.3 0.3 0.3"/>
            <joint name="robot0_joint2" pos="0 0 0" axis="0 0 1" limited="true" range="-2.8973 2.8973" armature="2.5" damping="0.1" frictionloss="0.1"/>
            <geom name="robot0_g13_vis" type="mesh" contype="0" conaffinity="0" group="1" material="robot0_Part__Feature024" mesh="robot0_link2_vis"/>
            <geom name="robot0_link2_collision" type="mesh" rgba="0 0.5 0 1" mesh="robot0_link2" group="3"/>
            <body name="robot0_link3" pos="0 -0.316 0" quat="0.707107 0.707107 0 0">
              <inertial pos="0.04 0 -0.05" mass="2" diaginertia="0.2 0.2 0.2"/>
              <joint name="robot0_joint3" pos="0 0 0" axis="0 0 1" limited="true" range="-2.8973 2.8973" armature="1.66667" damping="0.1" frictionloss="0.1"/>
              <geom name="robot0_g14_vis" type="mesh" contype="0" conaffinity="0" group="1" material="robot0_Part__Feature003_004_001_002" mesh="robot0_link3_vis_0"/>
              <geom name="robot0_g15_vis" type="mesh" contype="0" conaffinity="0" group="1" material="robot0_Part__Feature002_007_001_002" mesh="robot0_link3_vis_1"/>
              <geom name="robot0_g16_vis" type="mesh" contype="0" conaffinity="0" group="1" material="robot0_Part__Feature001_010_001_002" mesh="robot0_link3_vis_2"/>
              <geom name="robot0_g17_vis" type="mesh" contype="0" conaffinity="0" group="1" material="robot0_Part__Feature_001_001_001_002" mesh="robot0_link3_vis_3"/>
              <geom name="robot0_link3_collision" type="mesh" rgba="0 0.5 0 1" mesh="robot0_link3" group="3"/>
              <body name="robot0_link4" pos="0.0825 0 0" quat="0.707107 0.707107 0 0">
                <inertial pos="-0.04 0.05 0" mass="2" diaginertia="0.2 0.2 0.2"/>
                <joint name="robot0_joint4" pos="0 0 0" axis="0 0 1" limited="true" range="-3.0718 -0.0698" armature="1.25" damping="0.1" frictionloss="0.1"/>
                <geom name="robot0_g18_vis" type="mesh" contype="0" conaffinity="0" group="1" material="robot0_Part__Feature001_001_003_001" mesh="robot0_link4_vis_0"/>
                <geom name="robot0_g19_vis" type="mesh" contype="0" conaffinity="0" group="1" material="robot0_Part__Feature003_001_003_001" mesh="robot0_link4_vis_1"/>
                <geom name="robot0_g20_vis" type="mesh" contype="0" conaffinity="0" group="1" material="robot0_Part__Feature002_001_003_001" mesh="robot0_link4_vis_2"/>
                <geom name="robot0_g21_vis" type="mesh" contype="0" conaffinity="0" group="1" material="robot0_Part__Feature_002_003_001" mesh="robot0_link4_vis_3"/>
                <geom name="robot0_link4_collision" type="mesh" rgba="0 0.5 0 1" mesh="robot0_link4" group="3"/>
                <body name="robot0_link5" pos="-0.0825 0.384 0" quat="0.707107 -0.707107 0 0">
                  <inertial pos="0 0 -0.15" mass="2" diaginertia="0.2 0.2 0.2"/>
                  <joint name="robot0_joint5" pos="0 0 0" axis="0 0 1" limited="true" range="-2.8973 2.8973" armature="1" damping="0.1" frictionloss="0.1"/>
                  <geom name="robot0_g22_vis" type="mesh" contype="0" conaffinity="0" group="1" material="robot0_Shell001_001_001_003" mesh="robot0_link5_vis_0"/>
                  <geom name="robot0_g23_vis" type="mesh" contype="0" conaffinity="0" group="1" material="robot0_Shell_001_001_003" mesh="robot0_link5_vis_1"/>
                  <geom name="robot0_g24_vis" type="mesh" contype="0" conaffinity="0" group="1" material="robot0_Part__Feature_002_004_003" mesh="robot0_link5_vis_2"/>
                  <geom name="robot0_link5_collision" type="mesh" rgba="0 0.5 0 1" mesh="robot0_link5" group="3"/>
                  <body name="robot0_link6" quat="0.707107 0.707107 0 0">
                    <inertial pos="0.06 0 0" mass="1.5" diaginertia="0.1 0.1 0.1"/>
                    <joint name="robot0_joint6" pos="0 0 0" axis="0 0 1" limited="true" range="-0.0175 3.7525" armature="0.833333" damping="0.01" frictionloss="0.1"/>
                    <geom name="robot0_g25_vis" type="mesh" contype="0" conaffinity="0" group="1" material="robot0_Shell006_003_002_001" mesh="robot0_link6_vis_0"/>
                    <geom name="robot0_g26_vis" type="mesh" contype="0" conaffinity="0" group="1" material="robot0_Shell011_002_002_001" mesh="robot0_link6_vis_1"/>
                    <geom name="robot0_g27_vis" type="mesh" contype="0" conaffinity="0" group="1" material="robot0_Shell007_002_002_001" mesh="robot0_link6_vis_2"/>
                    <geom name="robot0_g28_vis" type="mesh" contype="0" conaffinity="0" group="1" material="robot0_Shell005_001_001_002_001" mesh="robot0_link6_vis_3"/>
                    <geom name="robot0_g29_vis" type="mesh" contype="0" conaffinity="0" group="1" material="robot0_Shell004_001_001_002_001" mesh="robot0_link6_vis_4"/>
                    <geom name="robot0_g30_vis" type="mesh" contype="0" conaffinity="0" group="1" material="robot0_Shell003_002_001_002_001" mesh="robot0_link6_vis_5"/>
                    <geom name="robot0_g31_vis" type="mesh" contype="0" conaffinity="0" group="1" material="robot0_Shell002_002_001_002_001" mesh="robot0_link6_vis_6"/>
                    <geom name="robot0_g32_vis" type="mesh" contype="0" conaffinity="0" group="1" material="robot0_Union001_001_001_002_001" mesh="robot0_link6_vis_7"/>
                    <geom name="robot0_g33_vis" type="mesh" contype="0" conaffinity="0" group="1" material="robot0_Union_001_001_002_001" mesh="robot0_link6_vis_8"/>
                    <geom name="robot0_g34_vis" type="mesh" contype="0" conaffinity="0" group="1" material="robot0_Face539_002_001_002_001" mesh="robot0_link6_vis_9"/>
                    <geom name="robot0_g35_vis" type="mesh" contype="0" conaffinity="0" group="1" material="robot0_Shell_003_001_002_001" mesh="robot0_link6_vis_10"/>
                    <geom name="robot0_g36_vis" type="mesh" contype="0" conaffinity="0" group="1" material="robot0_Face374_002_001_002_001" mesh="robot0_link6_vis_11"/>
                    <geom name="robot0_g37_vis" type="mesh" contype="0" conaffinity="0" group="1" material="robot0_Face065_002_001_002_001" mesh="robot0_link6_vis_12"/>
                    <geom name="robot0_g38_vis" type="mesh" contype="0" conaffinity="0" group="1" material="robot0_Face064_002_001_002_001" mesh="robot0_link6_vis_13"/>
                    <geom name="robot0_g39_vis" type="mesh" contype="0" conaffinity="0" group="1" material="robot0_Part__Feature002_006_001_002_001" mesh="robot0_link6_vis_14"/>
                    <geom name="robot0_g40_vis" type="mesh" contype="0" conaffinity="0" group="1" material="robot0_Part__Feature001_009_001_002_001" mesh="robot0_link6_vis_15"/>
                    <geom name="robot0_g41_vis" type="mesh" contype="0" conaffinity="0" group="1" material="robot0_Shell012_002_002_001" mesh="robot0_link6_vis_16"/>
                    <geom name="robot0_link6_collision" type="mesh" rgba="0 0.5 0 1" mesh="robot0_link6" group="3"/>
                    <body name="robot0_link7" pos="0.088 0 0" quat="0.707107 0.707107 0 0">
                      <inertial pos="0 0 0.08" mass="0.5" diaginertia="0.05 0.05 0.05"/>
                      <joint name="robot0_joint7" pos="0 0 0" axis="0 0 1" limited="true" range="-3.14 3.14" armature="0.714286" damping="0.01" frictionloss="0.1"/>
                      <geom name="robot0_g42_vis" type="mesh" contype="0" conaffinity="0" group="1" material="robot0_Part__Mirroring004_004_002" mesh="robot0_link7_vis_0"/>
                      <geom name="robot0_g43_vis" type="mesh" contype="0" conaffinity="0" group="1" material="robot0_Part__Mirroring001_004_002" mesh="robot0_link7_vis_1"/>
                      <geom name="robot0_g44_vis" type="mesh" contype="0" conaffinity="0" group="1" material="robot0_Part__Mirroring007_004_001" mesh="robot0_link7_vis_2"/>
                      <geom name="robot0_g45_vis" type="mesh" contype="0" conaffinity="0" group="1" material="robot0_Part__Mirroring006_004_001" mesh="robot0_link7_vis_3"/>
                      <geom name="robot0_g46_vis" type="mesh" contype="0" conaffinity="0" group="1" material="robot0_Part__Mirroring005_004_001" mesh="robot0_link7_vis_4"/>
                      <geom name="robot0_g47_vis" type="mesh" contype="0" conaffinity="0" group="1" material="robot0_Part__Mirroring003_004_001" mesh="robot0_link7_vis_5"/>
                      <geom name="robot0_g48_vis" type="mesh" contype="0" conaffinity="0" group="1" material="robot0_Part__Mirroring002_004_001" mesh="robot0_link7_vis_6"/>
                      <geom name="robot0_g49_vis" type="mesh" contype="0" conaffinity="0" group="1" material="robot0_Part__Mirroring_004_001" mesh="robot0_link7_vis_7"/>
                      <geom name="robot0_link7_collision" type="mesh" rgba="0 0.5 0 1" mesh="robot0_link7" group="3"/>
                      <body name="robot0_right_hand" pos="0 0 0.1065" quat="0.923785 0 0 -0.382911">
                      <inertial pos="0 0 0" mass="0.5" diaginertia="0.05 0.05 0.05"/>
                      <camera name="robot0_eye_in_hand" pos="0.1 0 -0.025" quat="0.0924 0.7011 0.7011 0.0924"  fovy="75"/>
                      <!-- <geom name="hand_camera_marker" type="sphere" size="0.03" pos="0.1 0 -0.025" quat="0.2706 0.6533 0.6533 0.2706" rgba="1 0 0 0.8" contype="0" conaffinity="0" group="0"/> -->
                        <body name="gripper0_gripper_base" quat="0.707107 0 0 -0.707107">
                          <inertial pos="0 0 0.17" quat="0.707107 0.707107 0 0" mass="0.3" diaginertia="0.09 0.07 0.05"/>
                          <geom name="gripper0_right_hand_visual" quat="0.707107 0 0 0.707107" type="mesh" contype="0" conaffinity="0" group="1" rgba="1 1 1 1" mesh="gripper0_right_hand_vis"/>
                          <geom name="gripper0_right_hand_collision" quat="0.707107 0 0 0.707107" type="mesh" rgba="0 0 0.5 1" mesh="gripper0_right_hand" group="3"/>
                          <site name="gripper0_right_ft_frame" pos="0 0 0" size="0.01" group="1" rgba="1 0 0 0"/>
                          <body name="gripper0_right_eef" pos="0 0 0.097">
                            <site name="gripper0_right_grip_site" pos="0 0 0" size="0.01" group="1" rgba="1 0 0 0"/>
                          </body>
                          <body name="gripper0_right_leftfinger" pos="0 0 0.0524" quat="0.707107 0 0 0.707107">
                            <inertial pos="0 0 0.05" mass="0.1" diaginertia="0.01 0.01 0.005"/>
                            <joint name="gripper0_right_finger_joint1" pos="0 0 0" axis="0 1 0" type="slide" limited="true" range="0 0.04" armature="1" damping="100" frictionloss="1"/>
                            <geom name="gripper0_right_finger1_visual" type="mesh" contype="0" conaffinity="0" group="1" rgba="0.499 0.499 0.499 1" mesh="gripper0_right_finger_vis"/>
                            <geom name="gripper0_right_finger1_collision" type="mesh" contype="0" condim="4" rgba="0 0 0.5 1" mesh="gripper0_right_finger" group="3"/>
                            <body name="gripper0_right_finger_joint1_tip" pos="0 0.0085 0.056">
                              <inertial pos="0 0 0" quat="0 0 0 1" mass="0.01" diaginertia="0.01 0.01 0.01"/>
                              <geom name="gripper0_right_finger1_pad_collision" size="0.008 0.004 0.008" pos="0 -0.005 -0.015" quat="0 0 0 1" type="box" friction="2 0.05" solref="0.01 0.5" rgba="0 0 0.5 1" group="3"/>
                            </body>
                          </body>
                          <body name="gripper0_right_rightfinger" pos="0 0 0.0524" quat="0.707107 0 0 0.707107">
                            <inertial pos="0 0 0.05" mass="0.1" diaginertia="0.01 0.01 0.005"/>
                            <joint name="gripper0_right_finger_joint2" pos="0 0 0" axis="0 1 0" type="slide" limited="true" range="-0.04 0" armature="1" damping="100" frictionloss="1"/>
                            <geom name="gripper0_right_finger2_visual" quat="0 0 0 1" type="mesh" contype="0" conaffinity="0" group="1" rgba="0.499 0.499 0.499 1" mesh="gripper0_right_finger_vis"/>
                            <geom name="gripper0_right_finger2_collision" quat="0 0 0 1" type="mesh" contype="0" condim="4" rgba="0 0 0.5 1" mesh="gripper0_right_finger" group="3"/>
                            <body name="gripper0_right_finger_joint2_tip" pos="0 -0.0085 0.056">
                            <inertial pos="0 0 0" quat="0 0 0 1" mass="0.01" diaginertia="0.01 0.01 0.01"/>
                            <geom name="gripper0_right_finger2_pad_collision" size="0.008 0.004 0.008" pos="0 0.005 -0.015" quat="0 0 0 1" type="box" friction="2 0.05" solref="0.01 0.5" rgba="0 0 0.5 1" group="3"/>
                            </body>
                          </body>
                      </body>
                    </body>
                  </body>
                </body>
              </body>
            </body>
          </body>
        </body>
      </body>
    </body>
  </body>
</mujocoinclude>
